[2024-10-24T05:58:59.540+0000] {taskinstance.py:1103} INFO - Dependencies all met for dep_context=non-requeueable deps ti=<TaskInstance: Extracao.executa_funcao manual__2024-10-24T05:58:46.810309+00:00 [queued]>
[2024-10-24T05:58:59.576+0000] {taskinstance.py:1103} INFO - Dependencies all met for dep_context=requeueable deps ti=<TaskInstance: Extracao.executa_funcao manual__2024-10-24T05:58:46.810309+00:00 [queued]>
[2024-10-24T05:58:59.577+0000] {taskinstance.py:1308} INFO - Starting attempt 1 of 2
[2024-10-24T05:58:59.638+0000] {taskinstance.py:1327} INFO - Executing <Task(PythonOperator): executa_funcao> on 2024-10-24 05:58:46.810309+00:00
[2024-10-24T05:58:59.663+0000] {standard_task_runner.py:57} INFO - Started process 1079 to run task
[2024-10-24T05:58:59.746+0000] {standard_task_runner.py:84} INFO - Running: ['***', 'tasks', 'run', 'Extracao', 'executa_funcao', 'manual__2024-10-24T05:58:46.810309+00:00', '--job-id', '77', '--raw', '--subdir', 'DAGS_FOLDER/dag.py', '--cfg-path', '/tmp/tmpw9i5j26s']
[2024-10-24T05:58:59.789+0000] {standard_task_runner.py:85} INFO - Job 77: Subtask executa_funcao
[2024-10-24T05:58:59.979+0000] {task_command.py:410} INFO - Running <TaskInstance: Extracao.executa_funcao manual__2024-10-24T05:58:46.810309+00:00 [running]> on host cf8624b924b9
[2024-10-24T05:59:00.397+0000] {taskinstance.py:1547} INFO - Exporting env vars: AIRFLOW_CTX_DAG_EMAIL='example@example.com' AIRFLOW_CTX_DAG_OWNER='Victor' AIRFLOW_CTX_DAG_ID='Extracao' AIRFLOW_CTX_TASK_ID='executa_funcao' AIRFLOW_CTX_EXECUTION_DATE='2024-10-24T05:58:46.810309+00:00' AIRFLOW_CTX_TRY_NUMBER='1' AIRFLOW_CTX_DAG_RUN_ID='manual__2024-10-24T05:58:46.810309+00:00'
[2024-10-24T05:59:00.606+0000] {taskinstance.py:1824} ERROR - Task failed with exception
Traceback (most recent call last):
  File "/home/airflow/.local/lib/python3.7/site-packages/airflow/operators/python.py", line 181, in execute
    return_value = self.execute_callable()
  File "/home/airflow/.local/lib/python3.7/site-packages/airflow/operators/python.py", line 198, in execute_callable
    return self.python_callable(*self.op_args, **self.op_kwargs)
  File "/opt/airflow/dags/dag.py", line 20, in extracao
    if not Colecao.find_one({'Nome': record['Nome'], 'Idade': record['Idade']}):
KeyError: 'Nome'
[2024-10-24T05:59:00.627+0000] {taskinstance.py:1350} INFO - Marking task as UP_FOR_RETRY. dag_id=Extracao, task_id=executa_funcao, execution_date=20241024T055846, start_date=20241024T055859, end_date=20241024T055900
[2024-10-24T05:59:00.670+0000] {standard_task_runner.py:109} ERROR - Failed to execute job 77 for task executa_funcao ('Nome'; 1079)
[2024-10-24T05:59:00.700+0000] {local_task_job_runner.py:225} INFO - Task exited with return code 1
[2024-10-24T05:59:00.758+0000] {taskinstance.py:2653} INFO - 0 downstream tasks scheduled from follow-on schedule check
