[2024-10-24T06:36:55.760+0000] {taskinstance.py:1103} INFO - Dependencies all met for dep_context=non-requeueable deps ti=<TaskInstance: Extracao.executa_funcao manual__2024-10-24T06:36:45.685489+00:00 [queued]>
[2024-10-24T06:36:55.825+0000] {taskinstance.py:1103} INFO - Dependencies all met for dep_context=requeueable deps ti=<TaskInstance: Extracao.executa_funcao manual__2024-10-24T06:36:45.685489+00:00 [queued]>
[2024-10-24T06:36:55.827+0000] {taskinstance.py:1308} INFO - Starting attempt 1 of 2
[2024-10-24T06:36:55.909+0000] {taskinstance.py:1327} INFO - Executing <Task(PythonOperator): executa_funcao> on 2024-10-24 06:36:45.685489+00:00
[2024-10-24T06:36:55.956+0000] {standard_task_runner.py:57} INFO - Started process 2134 to run task
[2024-10-24T06:36:55.982+0000] {standard_task_runner.py:84} INFO - Running: ['***', 'tasks', 'run', 'Extracao', 'executa_funcao', 'manual__2024-10-24T06:36:45.685489+00:00', '--job-id', '86', '--raw', '--subdir', 'DAGS_FOLDER/dag.py', '--cfg-path', '/tmp/tmphyqqc51r']
[2024-10-24T06:36:56.001+0000] {standard_task_runner.py:85} INFO - Job 86: Subtask executa_funcao
[2024-10-24T06:36:56.422+0000] {task_command.py:410} INFO - Running <TaskInstance: Extracao.executa_funcao manual__2024-10-24T06:36:45.685489+00:00 [running]> on host cf8624b924b9
[2024-10-24T06:36:57.049+0000] {taskinstance.py:1547} INFO - Exporting env vars: AIRFLOW_CTX_DAG_EMAIL='example@example.com' AIRFLOW_CTX_DAG_OWNER='Victor' AIRFLOW_CTX_DAG_ID='Extracao' AIRFLOW_CTX_TASK_ID='executa_funcao' AIRFLOW_CTX_EXECUTION_DATE='2024-10-24T06:36:45.685489+00:00' AIRFLOW_CTX_TRY_NUMBER='1' AIRFLOW_CTX_DAG_RUN_ID='manual__2024-10-24T06:36:45.685489+00:00'
[2024-10-24T06:36:57.255+0000] {taskinstance.py:1824} ERROR - Task failed with exception
Traceback (most recent call last):
  File "/home/airflow/.local/lib/python3.7/site-packages/airflow/operators/python.py", line 181, in execute
    return_value = self.execute_callable()
  File "/home/airflow/.local/lib/python3.7/site-packages/airflow/operators/python.py", line 198, in execute_callable
    return self.python_callable(*self.op_args, **self.op_kwargs)
  File "/opt/airflow/dags/dag.py", line 15, in extracao
    Colecao.create_index([('nome', 1), ('email', 1), ('telefone', 1), ('data_nascimento', 1)], unique=True)
  File "/home/airflow/.local/lib/python3.7/site-packages/pymongo/collection.py", line 2120, in create_index
    return self.__create_indexes([index], session, **cmd_options)[0]
  File "/home/airflow/.local/lib/python3.7/site-packages/pymongo/_csot.py", line 108, in csot_wrapper
    return func(self, *args, **kwargs)
  File "/home/airflow/.local/lib/python3.7/site-packages/pymongo/collection.py", line 2000, in __create_indexes
    session=session,
  File "/home/airflow/.local/lib/python3.7/site-packages/pymongo/collection.py", line 315, in _command
    user_fields=user_fields,
  File "/home/airflow/.local/lib/python3.7/site-packages/pymongo/helpers.py", line 342, in inner
    return func(*args, **kwargs)
  File "/home/airflow/.local/lib/python3.7/site-packages/pymongo/pool.py", line 1010, in command
    write_concern=write_concern,
  File "/home/airflow/.local/lib/python3.7/site-packages/pymongo/network.py", line 216, in command
    parse_write_concern_error=parse_write_concern_error,
  File "/home/airflow/.local/lib/python3.7/site-packages/pymongo/helpers.py", line 242, in _check_command_response
    raise DuplicateKeyError(errmsg, code, response, max_wire_version)
pymongo.errors.DuplicateKeyError: Index build failed: d4565ec4-dfb5-4c22-9c6e-31a260913645: Collection MeuBancoDeDados.pessoas ( 58dcc0ea-2aa3-4d1e-8289-51cb69948164 ) :: caused by :: E11000 duplicate key error collection: MeuBancoDeDados.pessoas index: nome_1_email_1_telefone_1_data_nascimento_1 dup key: { nome: "Alice Silva", email: "alice.silva@email.com", telefone: "(11) 98765-4321", data_nascimento: "1990-05-12" }, full error: {'ok': 0.0, 'errmsg': 'Index build failed: d4565ec4-dfb5-4c22-9c6e-31a260913645: Collection MeuBancoDeDados.pessoas ( 58dcc0ea-2aa3-4d1e-8289-51cb69948164 ) :: caused by :: E11000 duplicate key error collection: MeuBancoDeDados.pessoas index: nome_1_email_1_telefone_1_data_nascimento_1 dup key: { nome: "Alice Silva", email: "alice.silva@email.com", telefone: "(11) 98765-4321", data_nascimento: "1990-05-12" }', 'code': 11000, 'codeName': 'DuplicateKey', 'keyPattern': {'nome': 1, 'email': 1, 'telefone': 1, 'data_nascimento': 1}, 'keyValue': {'nome': 'Alice Silva', 'email': 'alice.silva@email.com', 'telefone': '(11) 98765-4321', 'data_nascimento': '1990-05-12'}}
[2024-10-24T06:36:57.297+0000] {taskinstance.py:1350} INFO - Marking task as UP_FOR_RETRY. dag_id=Extracao, task_id=executa_funcao, execution_date=20241024T063645, start_date=20241024T063655, end_date=20241024T063657
[2024-10-24T06:36:57.359+0000] {standard_task_runner.py:109} ERROR - Failed to execute job 86 for task executa_funcao (Index build failed: d4565ec4-dfb5-4c22-9c6e-31a260913645: Collection MeuBancoDeDados.pessoas ( 58dcc0ea-2aa3-4d1e-8289-51cb69948164 ) :: caused by :: E11000 duplicate key error collection: MeuBancoDeDados.pessoas index: nome_1_email_1_telefone_1_data_nascimento_1 dup key: { nome: "Alice Silva", email: "alice.silva@email.com", telefone: "(11) 98765-4321", data_nascimento: "1990-05-12" }, full error: {'ok': 0.0, 'errmsg': 'Index build failed: d4565ec4-dfb5-4c22-9c6e-31a260913645: Collection MeuBancoDeDados.pessoas ( 58dcc0ea-2aa3-4d1e-8289-51cb69948164 ) :: caused by :: E11000 duplicate key error collection: MeuBancoDeDados.pessoas index: nome_1_email_1_telefone_1_data_nascimento_1 dup key: { nome: "Alice Silva", email: "alice.silva@email.com", telefone: "(11) 98765-4321", data_nascimento: "1990-05-12" }', 'code': 11000, 'codeName': 'DuplicateKey', 'keyPattern': {'nome': 1, 'email': 1, 'telefone': 1, 'data_nascimento': 1}, 'keyValue': {'nome': 'Alice Silva', 'email': 'alice.silva@email.com', 'telefone': '(11) 98765-4321', 'data_nascimento': '1990-05-12'}}; 2134)
[2024-10-24T06:36:57.388+0000] {local_task_job_runner.py:225} INFO - Task exited with return code 1
[2024-10-24T06:36:57.514+0000] {taskinstance.py:2653} INFO - 0 downstream tasks scheduled from follow-on schedule check
